Workbook

Sheet START_HERE
A1: Fruit of the Spirit Reflection / Fruit of the Spirit 360 Starter Workbook
A2: Purpose | B2: One workbook for the self-only reflection and the future 360 peer version.
A3: Core Positioning | B3: This is not a label. It is a mirror for spiritual growth.
A4: Bridge Line | B4: The fruit reveals what is becoming visible in your life; DesignID helps you understand the God-given design through which that fruit is meant to be expressed.
A6: Recommended Build Order
A7: 1 | B7: Review Question_Bank.
A8: 2 | B8: Use Response_Intake as the raw form response tab.
A9: 3 | B9: Use Report_Export as the report-ready output row.
A10: 4 | B10: Use Report_Control to select a report row for preview/PDFMonkey.
A11: 5 | B11: Use PDFMonkey_Payload if you later build a DPG-style Make/PDFMonkey flow.
A13: Important Rule | B13: Open comments are for the peer/360 version only, not for the self-review version.
A15: Workbook Tab Map
A16: Tab Name | B16: Purpose | C16: Copy/Paste Status
A17: START_HERE | B17: Plain-language setup notes for the workbook. | C17: Create manually.
A18: Assessment_Config | B18: Core settings, scale labels, report positioning, and version details. | C18: Use rating-scale.tsv and core language from product brief.
A19: Question_Bank | B19: Master list of the 27 rating statements and definitions. | C19: Use question-bank.tsv.
A20: Participant_Setup | B20: One row per person receiving a report. | C20: Create from intake or manually.
A21: Response_Intake | B21: Raw form responses from self and peer reviewers. | C21: Use response-intake-columns.tsv as headers.
A22: Report_Queue | B22: Tracks which reports are ready, queued, generated, or sent. | C22: Create manually, same spirit as DPG.
A23: Report_Data | B23: Helper calculations and fruit averages by participant. | C23: Formula-driven.
A24: Report_Export | B24: Clean report-ready row for PDFMonkey or page rendering. | C24: Use report-export-columns.tsv as headers.
A25: Report_Control | B25: Select one Participant_ID to preview/test a report. | C25: Create manually.
A26: PDFMonkey_Payload | B26: Final payload fields if using the DPG-style PDFMonkey path. | C26: Can mirror Report_Export later.
A27: Version_Notes | B27: Change log for question, scoring, and report language changes. | C27: Create manually.

Sheet Assessment_Config
A1: Assessment Name - Self Version | B1: Fruit of the Spirit Reflection
A2: Assessment Name - Peer Version | B2: Fruit of the Spirit 360
A3: Review Types | B3: Self, Peer
A4: Core Positioning | B4: This is not a label. It is a mirror for spiritual growth.
A5: Bridge Line | B5: The fruit reveals what is becoming visible in your life; DesignID helps you understand the God-given design through which that fruit is meant to be expressed.
A7: Rating Scale
A8: Score | B8: Label | C8: Report Language
A9: 1 | B9: Rarely visible | C9: This fruit may be less visible right now and could become an intentional area of growth.
A10: 2 | B10: Occasionally visible | C10: This fruit appears at times, but may not yet be expressed consistently.
A11: 3 | B11: Sometimes visible | C11: This fruit is meaningfully present, with room for greater consistency and maturity.
A12: 4 | B12: Often visible | C12: This fruit is often visible and appears to be a growing strength.
A13: 5 | B13: Consistently visible | C13: This fruit is consistently visible and appears to be a mature, practiced expression.
A15: Forced Sort Prompts
A16: Mode | B16: Prompt | C16: Instruction
A17: Self | B17: Most Visible Fruit | C17: Select the three fruit that feel most consistently visible in your life right now.
A18: Self | B18: Growth Focus Fruit | C18: Select the three fruit you sense God may be inviting you to intentionally cultivate in this season.
A19: Peer | B19: Most Visible Fruit | C19: Select the three fruit that seem most consistently visible in this person's life right now.
A20: Peer | B20: Growth Focus Fruit | C20: Select the three fruit that may be most valuable for this person to intentionally cultivate in this season.
A22: Open Comment Field Rules
A23: Mode | B23: Field | C23: Use
A24: Self | B24: Peer_Comment_Strength | C24: Do not show.
A25: Self | B25: Peer_Comment_Growth | C25: Do not show.
A26: Self | B26: Peer_Comment_Encouragement | C26: Do not show.
A27: Peer | B27: Peer_Comment_Strength | C27: Optional: Where do you most clearly see fruit in this person's life?
A28: Peer | B28: Peer_Comment_Growth | C28: Optional: Where might growth or intentional cultivation be helpful?
A29: Peer | B29: Peer_Comment_Encouragement | C29: Optional: What encouragement would you offer this person?
A31: Report Language By Fruit
A32: Fruit | B32: High Reflection | C32: Growth Reflection | D32: Suggested Practice
A33: Love | B33: Love appears to be a visible and life-giving strength. This person likely moves toward others with care, service, and compassion. | C33: Growth in love may involve moving toward people more intentionally, especially when it is inconvenient or costly. | D33: Choose one person this week to serve quietly and specifically without needing recognition.
A34: Joy | B34: Joy appears to be a visible source of hope and perspective. This person may help others remember goodness even in imperfect circumstances. | C34: Growth in joy may involve practicing gratitude and learning to celebrate God's work without comparison. | D34: Write down three evidences of God's goodness each day for seven days.
A35: Peace | B35: Peace appears to be a visible form of steadiness. This person may help calm, reconcile, and stabilize the spaces they enter. | C35: Growth in peace may involve learning to pause, pray, and pursue reconciliation before reacting to anxiety or conflict. | D35: Before responding to tension, pause for one minute and ask, "What would make for peace here?"
A36: Patience | B36: Patience appears to be a visible strength in the way this person handles delay, process, and people. | C36: Growth in patience may involve giving people and processes more room without rushing, shaming, or withdrawing. | D36: Identify one slow process or difficult person and choose a faithful response before the next interaction.
A37: Kindness | B37: Kindness appears to be a visible expression of care through words, presence, and practical help. | C37: Growth in kindness may involve becoming more attentive to small opportunities to encourage and dignify others. | D37: Give one specific encouragement each day to someone who may not expect it.
A38: Goodness | B38: Goodness appears to be visible through integrity, conviction, and active commitment to what is right and life-giving. | C38: Growth in goodness may involve aligning private choices, public actions, and stated values more fully. | D38: Review one decision this week through the question, "What is the most faithful and life-giving option?"
A39: Faithfulness | B39: Faithfulness appears to be visible through reliability, loyalty, and steady follow-through over time. | C39: Growth in faithfulness may involve strengthening consistency where commitments, relationships, or responsibilities have become easy to neglect. | D39: Choose one commitment that needs renewed attention and take one concrete step of follow-through.
A40: Gentleness | B40: Gentleness appears to be visible as strength under control, expressed with humility and care. | C40: Growth in gentleness may involve bringing truth or strength with less pressure, harshness, or defensiveness. | D40: In one hard conversation, focus on being both truthful and tender.
A41: Self-Control | B41: Self-control appears to be visible through disciplined responses, habits, words, and choices. | C41: Growth in self-control may involve surrendering impulsive reactions and practicing wiser rhythms. | D41: Choose one recurring impulse and create a simple pause, prayer, or boundary before acting on it.

Sheet Question_Bank
A1: Fruit | B1: Code | C1: Definition | D1: Self Rating Statement | E1: Peer Rating Statement
A2: Love | B2: LOVE_01 | C2: Sacrificial care that moves toward others for their good. | D2: I move toward others with genuine care, even when it costs me time, comfort, or convenience. | E2: This person moves toward others with genuine care, even when it costs time, comfort, or convenience.
A3: Love | B3: LOVE_02 | C3: Sacrificial care that moves toward others for their good. | D3: I show concern for people as whole persons, not just for what they can accomplish or provide. | E3: This person shows concern for people as whole persons, not just for what they can accomplish or provide.
A4: Love | B4: LOVE_03 | C4: Sacrificial care that moves toward others for their good. | D4: I choose patience, service, and compassion when others are difficult, inconvenient, or different from me. | E4: This person chooses patience, service, and compassion when others are difficult, inconvenient, or different from them.
A5: Joy | B5: JOY_01 | C5: Deep gladness rooted in God that can remain present beyond circumstances. | D5: I am able to carry a steady gladness that is not dependent only on circumstances going my way. | E5: This person carries a steady gladness that is not dependent only on circumstances going their way.
A6: Joy | B6: JOY_02 | C6: Deep gladness rooted in God that can remain present beyond circumstances. | D6: I help create hope, gratitude, and life-giving perspective in the people around me. | E6: This person helps create hope, gratitude, and life-giving perspective in the people around them.
A7: Joy | B7: JOY_03 | C7: Deep gladness rooted in God that can remain present beyond circumstances. | D7: I can celebrate what God is doing in others without comparison, resentment, or competition. | E7: This person can celebrate what God is doing in others without comparison, resentment, or competition.
A8: Peace | B8: PEACE_01 | C8: Settled trust in God that brings steadiness, reconciliation, and calm. | D8: I remain grounded and steady when circumstances, people, or outcomes feel uncertain. | E8: This person remains grounded and steady when circumstances, people, or outcomes feel uncertain.
A9: Peace | B9: PEACE_02 | C9: Settled trust in God that brings steadiness, reconciliation, and calm. | D9: I help reduce anxiety, conflict, or confusion rather than adding to it. | E9: This person helps reduce anxiety, conflict, or confusion rather than adding to it.
A10: Peace | B10: PEACE_03 | C10: Settled trust in God that brings steadiness, reconciliation, and calm. | D10: I pursue reconciliation and wholeness when relationships become strained. | E10: This person pursues reconciliation and wholeness when relationships become strained.
A11: Patience | B11: PATIENCE_01 | C11: Steadfast endurance with people, process, weakness, and delay. | D11: I can stay faithful and composed when progress is slow or outcomes take longer than expected. | E11: This person stays faithful and composed when progress is slow or outcomes take longer than expected.
A12: Patience | B12: PATIENCE_02 | C12: Steadfast endurance with people, process, weakness, and delay. | D12: I give people room to grow without rushing, shaming, or giving up on them too quickly. | E12: This person gives people room to grow without rushing, shaming, or giving up on them too quickly.
... A28: Self-Control | B28: SELFCONTROL_03 | C28: Spirit-formed discipline that governs desires, reactions, words, and choices. | D28: I can delay immediate desires for what is wiser, healthier, or more faithful. | E28: This person can delay immediate desires for what is wiser, healthier, or more faithful.

Sheet Participant_Setup
A1: Participant_ID | B1: Participant_Name | C1: Participant_Email | D1: Assessment_Mode | E1: Status | F1: Created_Date | G1: Self_Form_Link | H1: Peer_Form_Link | I1: Notes

Sheet Response_Intake
A1: Timestamp | B1: Participant_ID | C1: Participant_Name | D1: Review_Type | E1: Reviewer_Name | F1: Reviewer_Email | G1: Relationship | H1: LOVE_01 | I1: LOVE_02 | J1: LOVE_03 | K1: JOY_01 | L1: JOY_02 | M1: JOY_03 | N1: PEACE_01 | O1: PEACE_02 | P1: PEACE_03 | Q1: PATIENCE_01 | R1: PATIENCE_02 | S1: PATIENCE_03 | T1: KINDNESS_01 | U1: KINDNESS_02 | V1: KINDNESS_03 | W1: GOODNESS_01 | X1: GOODNESS_02 | Y1: GOODNESS_03 | Z1: FAITHFULNESS_01 | AA1: FAITHFULNESS_02 | AB1: FAITHFULNESS_03 | AC1: GENTLENESS_01 | AD1: GENTLENESS_02 | AE1: GENTLENESS_03 | AF1: SELFCONTROL_01 | AG1: SELFCONTROL_02 | AH1: SELFCONTROL_03 | AI1: Most_Visible_1 | AJ1: Most_Visible_2 | AK1: Most_Visible_3 | AL1: Growth_Focus_1 | AM1: Growth_Focus_2 | AN1: Growth_Focus_3 | AO1: Peer_Comment_Strength | AP1: Peer_Comment_Growth | AQ1: Peer_Comment_Encouragement | AR1: Love_Avg | AS1: Joy_Avg | AT1: Peace_Avg | AU1: Patience_Avg | AV1: Kindness_Avg | AW1: Goodness_Avg | AX1: Faithfulness_Avg | AY1: Gentleness_Avg | AZ1: SelfControl_Avg | BA1: Reviewer_Group | BB1: Response_ID | BC1: Invite_Token | BD1: DesignID_Status | BE1: DesignID_Primary | BF1: DesignID_Secondary | BG1: Love_Pressure | BH1: Joy_Pressure | BI1: Peace_Pressure | BJ1: Patience_Pressure | BK1: Kindness_Pressure | BL1: Goodness_Pressure | BM1: Faithfulness_Pressure | BN1: Gentleness_Pressure | BO1: SelfControl_Pressure | BP1: Final_Reflection | BQ1: Observer_Encouragement | BR1: Observer_Growth_Invitation
A2: 2026-07-17T18:10:00Z | B2: FL360-SAMPLE | C2: Sample Person | D2: Self | E2: Sample Person | F2: sample@example.com | G2: Self | H2: 4 | I2: 5 | J2: 4 | K2: 3 | L2: 4 | M2: 4 | N2: 4 | O2: 4 | P2: 5 | Q2: 3 | R2: 3 | S2: 4 | T2: 5 | U2: 4 | V2: 5 | W2: 4 | X2: 4 | Y2: 4 | Z2: 5 | AA2: 4 | AB2: 4 | AC2: 3 | AD2: 4 | AE2: 3 | AF2: 3 | AG2: 4 | AH2: 3 | AI2: Kindness | AJ2: Faithfulness | AK2: Peace | AL2: Patience | AM2: Self-control | AN2: Joy | AR2: =IF(COUNTA(H2:J2)=0,"",AVERAGE(H2:J2)) -> 4.3333333 | AS2: =IF(COUNTA(K2:M2)=0,"",AVERAGE(K2:M2)) -> 3.6666667 | AT2: =IF(COUNTA(N2:P2)=0,"",AVERAGE(N2:P2)) -> 4.3333333 | AU2: =IF(COUNTA(Q2:S2)=0,"",AVERAGE(Q2:S2)) -> 3.3333333 | AV2: =IF(COUNTA(T2:V2)=0,"",AVERAGE(T2:V2)) -> 4.6666667 | AW2: =IF(COUNTA(W2:Y2)=0,"",AVERAGE(W2:Y2)) -> 4 | AX2: =IF(COUNTA(Z2:AB2)=0,"",AVERAGE(Z2:AB2)) -> 4.3333333 | AY2: =IF(COUNTA(AC2:AE2)=0,"",AVERAGE(AC2:AE2)) -> 3.3333333 | AZ2: =IF(COUNTA(AF2:AH2)=0,"",AVERAGE(AF2:AH2)) -> 3.3333333 | BA2: Self | BB2: RESP-SAMPLE-SELF | BC2: SELF-SAMPLE | BD2: Known | BE2: Shepherd | BF2: Steward | BG2: 4 | BH2: 3 | BI2: 4 | BJ2: 3 | BK2: 4 | BL2: 4 | BM2: 4 | BN2: 3 | BO2: 3 | BP2: I want the Holy Spirit to grow patience and self-control in this season.
A3: 2026-07-17T18:11:00Z | B3: FL360-SAMPLE | C3: Sample Person | D3: Peer | E3: Observer One | F3: observer1@example.com | G3: Close friend | H3: 5 | I3: 5 | J3: 4 | K3: 4 | L3: 4 | M3: 4 | N3: 5 | O3: 4 | P3: 5 | Q3: 3 | R3: 4 | S3: 3 | T3: 5 | U3: 5 | V3: 5 | W3: 4 | X3: 4 | Y3: 4 | Z3: 5 | AA3: 4 | AB3: 5 | AC3: 4 | AD3: 4 | AE3: 4 | AF3: 3 | AG3: 3 | AH3: 4 | AI3: Love | AJ3: Kindness | AK3: Peace | AL3: Self-control | AM3: Patience | AN3: Gentleness | AO3: They move toward people with care and practical help. | AP3: They could slow down when frustrated or overloaded. | AQ3: Their care is very visible and encouraging. | AR3: =IF(COUNTA(H3:J3)=0,"",AVERAGE(H3:J3)) -> 4.6666667 | AS3: =IF(COUNTA(K3:M3)=0,"",AVERAGE(K3:M3)) -> 4 | AT3: =IF(COUNTA(N3:P3)=0,"",AVERAGE(N3:P3)) -> 4.6666667 | AU3: =IF(COUNTA(Q3:S3)=0,"",AVERAGE(Q3:S3)) -> 3.3333333 | AV3: =IF(COUNTA(T3:V3)=0,"",AVERAGE(T3:V3)) -> 5 | AW3: =IF(COUNTA(W3:Y3)=0,"",AVERAGE(W3:Y3)) -> 4 | AX3: =IF(COUNTA(Z3:AB3)=0,"",AVERAGE(Z3:AB3)) -> 4.6666667 | AY3: =IF(COUNTA(AC3:AE3)=0,"",AVERAGE(AC3:AE3)) -> 4 | AZ3: =IF(COUNTA(AF3:AH3)=0,"",AVERAGE(AF3:AH3)) -> 3.3333333 | BA3: Close Relationship | BB3: RESP-SAMPLE-OBS1 | BC3: OBS-SAMPLE-1 | BD3: Known | BE3: Shepherd | BF3: Steward | BG3: 5 | BH3: 4 | BI3: 4 | BJ3: 3 | BK3: 5 | BL3: 4 | BM3: 4 | BN3: 3 | BO3: 3 | BQ3: Their care for people feels genuine. | BR3: Patience under pressure may be a growth invitation.
A4: 2026-07-17T18:12:00Z | B4: FL360-SAMPLE | C4: Sample Person | D4: Peer | E4: Observer Two | F4: observer2@example.com | G4: Ministry teammate | H4: 4 | I4: 4 | J4: 5 | K4: 3 | L4: 4 | M4: 3 | N4: 4 | O4: 4 | P4: 4 | Q4: 3 | R4: 3 | S4: 3 | T4: 4 | U4: 5 | V4: 4 | W4: 4 | X4: 4 | Y4: 5 | Z4: 5 | AA4: 5 | AB4: 4 | AC4: 4 | AD4: 4 | AE4: 4 | AF4: 3 | AG4: 4 | AH4: 3 | AI4: Goodness | AJ4: Faithfulness | AK4: Kindness | AL4: Patience | AM4: Joy | AN4: Gentleness | AO4: They are dependable and choose what is right even when it costs them. | AP4: They can carry too much and get quiet instead of asking for help. | AQ4: Their faithfulness builds trust. | AR4: =IF(COUNTA(H4:J4)=0,"",AVERAGE(H4:J4)) -> 4.3333333 | AS4: =IF(COUNTA(K4:M4)=0,"",AVERAGE(K4:M4)) -> 3.3333333 | AT4: =IF(COUNTA(N4:P4)=0,"",AVERAGE(N4:P4)) -> 4 | AU4: =IF(COUNTA(Q4:S4)=0,"",AVERAGE(Q4:S4)) -> 3 | AV4: =IF(COUNTA(T4:V4)=0,"",AVERAGE(T4:V4)) -> 4.3333333 | AW4: =IF(COUNTA(W4:Y4)=0,"",AVERAGE(W4:Y4)) -> 4.3333333 | AX4: =IF(COUNTA(Z4:AB4)=0,"",AVERAGE(Z4:AB4)) -> 4.6666667 | AY4: =IF(COUNTA(AC4:AE4)=0,"",AVERAGE(AC4:AE4)) -> 4 | AZ4: =IF(COUNTA(AF4:AH4)=0,"",AVERAGE(AF4:AH4)) -> 3.3333333 | BA4: Ministry / Team | BB4: RESP-SAMPLE-OBS2 | BC4: OBS-SAMPLE-2 | BD4: Known | BE4: Shepherd | BF4: Steward | BG4: 4 | BH4: 3 | BI4: 4 | BJ4: 3 | BK4: 4 | BL4: 5 | BM4: 5 | BN4: 3 | BO4: 3 | BQ4: Their goodness and faithfulness are steady. | BR4: Gentleness and patience under pressure could grow.
A5: 2026-07-17T18:13:00Z | B5: FL360-SAMPLE | C5: Sample Person | D5: Peer | E5: Observer Three | F5: observer3@example.com | G5: Mentor / leader | H5: 4 | I5: 5 | J5: 5 | K5: 4 | L5: 4 | M5: 4 | N5: 4 | O5: 5 | P5: 5 | Q5: 4 | R5: 3 | S5: 4 | T5: 5 | U5: 4 | V5: 5 | W5: 4 | X5: 5 | Y5: 4 | Z5: 5 | AA5: 5 | AB5: 5 | AC5: 4 | AD5: 5 | AE5: 4 | AF5: 4 | AG5: 4 | AH5: 4 | AI5: Peace | AJ5: Love | AK5: Faithfulness | AL5: Self-control | AM5: Patience | AN5: Joy | AO5: They bring peace and steadiness into stressful situations. | AP5: They should keep practicing measured responses when tired. | AQ5: Their presence is settling and trustworthy. | AR5: =IF(COUNTA(H5:J5)=0,"",AVERAGE(H5:J5)) -> 4.6666667 | AS5: =IF(COUNTA(K5:M5)=0,"",AVERAGE(K5:M5)) -> 4 | AT5: =IF(COUNTA(N5:P5)=0,"",AVERAGE(N5:P5)) -> 4.6666667 | AU5: =IF(COUNTA(Q5:S5)=0,"",AVERAGE(Q5:S5)) -> 3.6666667 | AV5: =IF(COUNTA(T5:V5)=0,"",AVERAGE(T5:V5)) -> 4.6666667 | AW5: =IF(COUNTA(W5:Y5)=0,"",AVERAGE(W5:Y5)) -> 4.3333333 | AX5: =IF(COUNTA(Z5:AB5)=0,"",AVERAGE(Z5:AB5)) -> 5 | AY5: =IF(COUNTA(AC5:AE5)=0,"",AVERAGE(AC5:AE5)) -> 4.3333333 | AZ5: =IF(COUNTA(AF5:AH5)=0,"",AVERAGE(AF5:AH5)) -> 4 | BA5: Mentor / Leader | BB5: RESP-SAMPLE-OBS3 | BC5: OBS-SAMPLE-3 | BD5: Known | BE5: Shepherd | BF5: Steward | BG5: 4 | BH5: 4 | BI5: 5 | BJ5: 3 | BK5: 4 | BL5: 4 | BM5: 5 | BN5: 4 | BO5: 3 | BQ5: Their peaceful presence is noticeable. | BR5: Self-control under pressure is worth intentional practice.
AR6: =IF(COUNTA(H6:J6)=0,"",AVERAGE(H6:J6)) | AS6: =IF(COUNTA(K6:M6)=0,"",AVERAGE(K6:M6)) | AT6: =IF(COUNTA(N6:P6)=0,"",AVERAGE(N6:P6)) | AU6: =IF(COUNTA(Q6:S6)=0,"",AVERAGE(Q6:S6)) | AV6: =IF(COUNTA(T6:V6)=0,"",AVERAGE(T6:V6)) | AW6: =IF(COUNTA(W6:Y6)=0,"",AVERAGE(W6:Y6)) | AX6: =IF(COUNTA(Z6:AB6)=0,"",AVERAGE(Z6:AB6)) | AY6: =IF(COUNTA(AC6:AE6)=0,"",AVERAGE(AC6:AE6)) | AZ6: =IF(COUNTA(AF6:AH6)=0,"",AVERAGE(AF6:AH6))
AR7: =IF(COUNTA(H7:J7)=0,"",AVERAGE(H7:J7)) | AS7: =IF(COUNTA(K7:M7)=0,"",AVERAGE(K7:M7)) | AT7: =IF(COUNTA(N7:P7)=0,"",AVERAGE(N7:P7)) | AU7: =IF(COUNTA(Q7:S7)=0,"",AVERAGE(Q7:S7)) | AV7: =IF(COUNTA(T7:V7)=0,"",AVERAGE(T7:V7)) | AW7: =IF(COUNTA(W7:Y7)=0,"",AVERAGE(W7:Y7)) | AX7: =IF(COUNTA(Z7:AB7)=0,"",AVERAGE(Z7:AB7)) | AY7: =IF(COUNTA(AC7:AE7)=0,"",AVERAGE(AC7:AE7)) | AZ7: =IF(COUNTA(AF7:AH7)=0,"",AVERAGE(AF7:AH7))
AR8: =IF(COUNTA(H8:J8)=0,"",AVERAGE(H8:J8)) | AS8: =IF(COUNTA(K8:M8)=0,"",AVERAGE(K8:M8)) | AT8: =IF(COUNTA(N8:P8)=0,"",AVERAGE(N8:P8)) | AU8: =IF(COUNTA(Q8:S8)=0,"",AVERAGE(Q8:S8)) | AV8: =IF(COUNTA(T8:V8)=0,"",AVERAGE(T8:V8)) | AW8: =IF(COUNTA(W8:Y8)=0,"",AVERAGE(W8:Y8)) | AX8: =IF(COUNTA(Z8:AB8)=0,"",AVERAGE(Z8:AB8)) | AY8: =IF(COUNTA(AC8:AE8)=0,"",AVERAGE(AC8:AE8)) | AZ8: =IF(COUNTA(AF8:AH8)=0,"",AVERAGE(AF8:AH8))
AR9: =IF(COUNTA(H9:J9)=0,"",AVERAGE(H9:J9)) | AS9: =IF(COUNTA(K9:M9)=0,"",AVERAGE(K9:M9)) | AT9: =IF(COUNTA(N9:P9)=0,"",AVERAGE(N9:P9)) | AU9: =IF(COUNTA(Q9:S9)=0,"",AVERAGE(Q9:S9)) | AV9: =IF(COUNTA(T9:V9)=0,"",AVERAGE(T9:V9)) | AW9: =IF(COUNTA(W9:Y9)=0,"",AVERAGE(W9:Y9)) | AX9: =IF(COUNTA(Z9:AB9)=0,"",AVERAGE(Z9:AB9)) | AY9: =IF(COUNTA(AC9:AE9)=0,"",AVERAGE(AC9:AE9)) | AZ9: =IF(COUNTA(AF9:AH9)=0,"",AVERAGE(AF9:AH9))
AR10: =IF(COUNTA(H10:J10)=0,"",AVERAGE(H10:J10)) | AS10: =IF(COUNTA(K10:M10)=0,"",AVERAGE(K10:M10)) | AT10: =IF(COUNTA(N10:P10)=0,"",AVERAGE(N10:P10)) | AU10: =IF(COUNTA(Q10:S10)=0,"",AVERAGE(Q10:S10)) | AV10: =IF(COUNTA(T10:V10)=0,"",AVERAGE(T10:V10)) | AW10: =IF(COUNTA(W10:Y10)=0,"",AVERAGE(W10:Y10)) | AX10: =IF(COUNTA(Z10:AB10)=0,"",AVERAGE(Z10:AB10)) | AY10: =IF(COUNTA(AC10:AE10)=0,"",AVERAGE(AC10:AE10)) | AZ10: =IF(COUNTA(AF10:AH10)=0,"",AVERAGE(AF10:AH10))
AR11: =IF(COUNTA(H11:J11)=0,"",AVERAGE(H11:J11)) | AS11: =IF(COUNTA(K11:M11)=0,"",AVERAGE(K11:M11)) | AT11: =IF(COUNTA(N11:P11)=0,"",AVERAGE(N11:P11)) | AU11: =IF(COUNTA(Q11:S11)=0,"",AVERAGE(Q11:S11)) | AV11: =IF(COUNTA(T11:V11)=0,"",AVERAGE(T11:V11)) | AW11: =IF(COUNTA(W11:Y11)=0,"",AVERAGE(W11:Y11)) | AX11: =IF(COUNTA(Z11:AB11)=0,"",AVERAGE(Z11:AB11)) | AY11: =IF(COUNTA(AC11:AE11)=0,"",AVERAGE(AC11:AE11)) | AZ11: =IF(COUNTA(AF11:AH11)=0,"",AVERAGE(AF11:AH11))
AR12: =IF(COUNTA(H12:J12)=0,"",AVERAGE(H12:J12)) | AS12: =IF(COUNTA(K12:M12)=0,"",AVERAGE(K12:M12)) | AT12: =IF(COUNTA(N12:P12)=0,"",AVERAGE(N12:P12)) | AU12: =IF(COUNTA(Q12:S12)=0,"",AVERAGE(Q12:S12)) | AV12: =IF(COUNTA(T12:V12)=0,"",AVERAGE(T12:V12)) | AW12: =IF(COUNTA(W12:Y12)=0,"",AVERAGE(W12:Y12)) | AX12: =IF(COUNTA(Z12:AB12)=0,"",AVERAGE(Z12:AB12)) | AY12: =IF(COUNTA(AC12:AE12)=0,"",AVERAGE(AC12:AE12)) | AZ12: =IF(COUNTA(AF12:AH12)=0,"",AVERAGE(AF12:AH12))
AR13: =IF(COUNTA(H13:J13)=0,"",AVERAGE(H13:J13)) | AS13: =IF(COUNTA(K13:M13)=0,"",AVERAGE(K13:M13)) | AT13: =IF(COUNTA(N13:P13)=0,"",AVERAGE(N13:P13)) | AU13: =IF(COUNTA(Q13:S13)=0,"",AVERAGE(Q13:S13)) | AV13: =IF(COUNTA(T13:V13)=0,"",AVERAGE(T13:V13)) | AW13: =IF(COUNTA(W13:Y13)=0,"",AVERAGE(W13:Y13)) | AX13: =IF(COUNTA(Z13:AB13)=0,"",AVERAGE(Z13:AB13)) | AY13: =IF(COUNTA(AC13:AE13)=0,"",AVERAGE(AC13:AE13)) | AZ13: =IF(COUNTA(AF13:AH13)=0,"",AVERAGE(AF13:AH13))
AR14: =IF(COUNTA(H14:J14)=0,"",AVERAGE(H14:J14)) | AS14: =IF(COUNTA(K14:M14)=0,"",AVERAGE(K14:M14)) | AT14: =IF(COUNTA(N14:P14)=0,"",AVERAGE(N14:P14)) | AU14: =IF(COUNTA(Q14:S14)=0,"",AVERAGE(Q14:S14)) | AV14: =IF(COUNTA(T14:V14)=0,"",AVERAGE(T14:V14)) | AW14: =IF(COUNTA(W14:Y14)=0,"",AVERAGE(W14:Y14)) | AX14: =IF(COUNTA(Z14:AB14)=0,"",AVERAGE(Z14:AB14)) | AY14: =IF(COUNTA(AC14:AE14)=0,"",AVERAGE(AC14:AE14)) | AZ14: =IF(COUNTA(AF14:AH14)=0,"",AVERAGE(AF14:AH14))
AR15: =IF(COUNTA(H15:J15)=0,"",AVERAGE(H15:J15)) | AS15: =IF(COUNTA(K15:M15)=0,"",AVERAGE(K15:M15)) | AT15: =IF(COUNTA(N15:P15)=0,"",AVERAGE(N15:P15)) | AU15: =IF(COUNTA(Q15:S15)=0,"",AVERAGE(Q15:S15)) | AV15: =IF(COUNTA(T15:V15)=0,"",AVERAGE(T15:V15)) | AW15: =IF(COUNTA(W15:Y15)=0,"",AVERAGE(W15:Y15)) | AX15: =IF(COUNTA(Z15:AB15)=0,"",AVERAGE(Z15:AB15)) | AY15: =IF(COUNTA(AC15:AE15)=0,"",AVERAGE(AC15:AE15)) | AZ15: =IF(COUNTA(AF15:AH15)=0,"",AVERAGE(AF15:AH15))
AR16: =IF(COUNTA(H16:J16)=0,"",AVERAGE(H16:J16)) | AS16: =IF(COUNTA(K16:M16)=0,"",AVERAGE(K16:M16)) | AT16: =IF(COUNTA(N16:P16)=0,"",AVERAGE(N16:P16)) | AU16: =IF(COUNTA(Q16:S16)=0,"",AVERAGE(Q16:S16)) | AV16: =IF(COUNTA(T16:V16)=0,"",AVERAGE(T16:V16)) | AW16: =IF(COUNTA(W16:Y16)=0,"",AVERAGE(W16:Y16)) | AX16: =IF(COUNTA(Z16:AB16)=0,"",AVERAGE(Z16:AB16)) | AY16: =IF(COUNTA(AC16:AE16)=0,"",AVERAGE(AC16:AE16)) | AZ16: =IF(COUNTA(AF16:AH16)=0,"",AVERAGE(AF16:AH16))
AR17: =IF(COUNTA(H17:J17)=0,"",AVERAGE(H17:J17)) | AS17: =IF(COUNTA(K17:M17)=0,"",AVERAGE(K17:M17)) | AT17: =IF(COUNTA(N17:P17)=0,"",AVERAGE(N17:P17)) | AU17: =IF(COUNTA(Q17:S17)=0,"",AVERAGE(Q17:S17)) | AV17: =IF(COUNTA(T17:V17)=0,"",AVERAGE(T17:V17)) | AW17: =IF(COUNTA(W17:Y17)=0,"",AVERAGE(W17:Y17)) | AX17: =IF(COUNTA(Z17:AB17)=0,"",AVERAGE(Z17:AB17)) | AY17: =IF(COUNTA(AC17:AE17)=0,"",AVERAGE(AC17:AE17)) | AZ17: =IF(COUNTA(AF17:AH17)=0,"",AVERAGE(AF17:AH17))
... AR200: =IF(COUNTA(H200:J200)=0,"",AVERAGE(H200:J200)) | AS200: =IF(COUNTA(K200:M200)=0,"",AVERAGE(K200:M200)) | AT200: =IF(COUNTA(N200:P200)=0,"",AVERAGE(N200:P200)) | AU200: =IF(COUNTA(Q200:S200)=0,"",AVERAGE(Q200:S200)) | AV200: =IF(COUNTA(T200:V200)=0,"",AVERAGE(T200:V200)) | AW200: =IF(COUNTA(W200:Y200)=0,"",AVERAGE(W200:Y200)) | AX200: =IF(COUNTA(Z200:AB200)=0,"",AVERAGE(Z200:AB200)) | AY200: =IF(COUNTA(AC200:AE200)=0,"",AVERAGE(AC200:AE200)) | AZ200: =IF(COUNTA(AF200:AH200)=0,"",AVERAGE(AF200:AH200))

Sheet Report_Queue
A1: Participant_ID | B1: Participant_Name | C1: Assessment_Mode | D1: Self_Complete | E1: Peer_Response_Count | F1: Report_Status | G1: Queued_Date | H1: Generated_Date | I1: Sent_Date | J1: Notes

Sheet Report_Data
A1: Report_Data
A2: Purpose | B2: Intermediate calculation layer. For v1, formulas can live in Report_Export. Use this tab later if the workbook gets crowded.
A4: DPG-style spine | B4: Response_Intake -> Report_Data -> Report_Export -> Report_Control -> PDFMonkey_Payload

Sheet Report_Export
A1: Participant_ID | B1: Participant_Name | C1: Self_Overall | D1: Peer_Overall | E1: Overall_Gap | F1: Self_Love | G1: Peer_Love | H1: Love_Gap | I1: Self_Joy | J1: Peer_Joy | K1: Joy_Gap | L1: Self_Peace | M1: Peer_Peace | N1: Peace_Gap | O1: Self_Patience | P1: Peer_Patience | Q1: Patience_Gap | R1: Self_Kindness | S1: Peer_Kindness | T1: Kindness_Gap | U1: Self_Goodness | V1: Peer_Goodness | W1: Goodness_Gap | X1: Self_Faithfulness | Y1: Peer_Faithfulness | Z1: Faithfulness_Gap | AA1: Self_Gentleness | AB1: Peer_Gentleness | AC1: Gentleness_Gap | AD1: Self_SelfControl | AE1: Peer_SelfControl | AF1: SelfControl_Gap | AG1: Top_Self_Fruit | AH1: Top_Peer_Fruit | AI1: Growth_Focus_Fruit | AJ1: Most_Visible_List | AK1: Growth_Focus_List | AL1: Peer_Strength_Comments | AM1: Peer_Growth_Comments | AN1: Peer_Encouragement_Comments
C2: =IFERROR(AVERAGE(F2,I2,L2,O2,R2,U2,X2,AA2,AD2),"") | D2: =IFERROR(AVERAGE(G2,J2,M2,P2,S2,V2,Y2,AB2,AE2),"") | E2: =IF(OR(C2="",D2=""),"",C2-D2) | H2: =IF(OR(F2="",G2=""),"",F2-G2) | K2: =IF(OR(I2="",J2=""),"",I2-J2) | N2: =IF(OR(L2="",M2=""),"",L2-M2) | Q2: =IF(OR(O2="",P2=""),"",O2-P2) | T2: =IF(OR(R2="",S2=""),"",R2-S2) | W2: =IF(OR(U2="",V2=""),"",U2-V2) | Z2: =IF(OR(X2="",Y2=""),"",X2-Y2) | AC2: =IF(OR(AA2="",AB2=""),"",AA2-AB2) | AF2: =IF(OR(AD2="",AE2=""),"",AD2-AE2)

Sheet Report_Control
A1: Setting | B1: Value | C1: Notes
A2: Report_Export_Row | B2: 2 | C2: Change this row number to preview/generate a different report.
A3: Participant_ID | B3: {=INDEX(Report_Export!A:A,B2)} | C3: Pulled from Report_Export.
A4: Participant_Name | B4: {=INDEX(Report_Export!B:B,B2)} | C4: Pulled from Report_Export.

Sheet PDFMonkey_Payload
A1: participant_id | B1: participant_name | C1: self_overall | D1: peer_overall | E1: overall_gap | F1: self_love | G1: peer_love | H1: love_gap | I1: self_joy | J1: peer_joy | K1: joy_gap | L1: self_peace | M1: peer_peace | N1: peace_gap | O1: self_patience | P1: peer_patience | Q1: patience_gap | R1: self_kindness | S1: peer_kindness | T1: kindness_gap | U1: self_goodness | V1: peer_goodness | W1: goodness_gap | X1: self_faithfulness | Y1: peer_faithfulness | Z1: faithfulness_gap | AA1: self_gentleness | AB1: peer_gentleness | AC1: gentleness_gap | AD1: self_selfcontrol | AE1: peer_selfcontrol | AF1: selfcontrol_gap | AG1: top_self_fruit | AH1: top_peer_fruit | AI1: growth_focus_fruit | AJ1: most_visible_list | AK1: growth_focus_list | AL1: peer_strength_comments | AM1: peer_growth_comments | AN1: peer_encouragement_comments
A2: {=INDEX(Report_Export!A:A,Report_Control!$B$2)} | B2: {=INDEX(Report_Export!B:B,Report_Control!$B$2)} | C2: {=INDEX(Report_Export!C:C,Report_Control!$B$2)} | D2: {=INDEX(Report_Export!D:D,Report_Control!$B$2)} | E2: {=INDEX(Report_Export!E:E,Report_Control!$B$2)} | F2: {=INDEX(Report_Export!F:F,Report_Control!$B$2)} | G2: {=INDEX(Report_Export!G:G,Report_Control!$B$2)} | H2: {=INDEX(Report_Export!H:H,Report_Control!$B$2)} | I2: {=INDEX(Report_Export!I:I,Report_Control!$B$2)} | J2: {=INDEX(Report_Export!J:J,Report_Control!$B$2)} | K2: {=INDEX(Report_Export!K:K,Report_Control!$B$2)} | L2: {=INDEX(Report_Export!L:L,Report_Control!$B$2)} | M2: {=INDEX(Report_Export!M:M,Report_Control!$B$2)} | N2: {=INDEX(Report_Export!N:N,Report_Control!$B$2)} | O2: {=INDEX(Report_Export!O:O,Report_Control!$B$2)} | P2: {=INDEX(Report_Export!P:P,Report_Control!$B$2)} | Q2: {=INDEX(Report_Export!Q:Q,Report_Control!$B$2)} | R2: {=INDEX(Report_Export!R:R,Report_Control!$B$2)} | S2: {=INDEX(Report_Export!S:S,Report_Control!$B$2)} | T2: {=INDEX(Report_Export!T:T,Report_Control!$B$2)} | U2: {=INDEX(Report_Export!U:U,Report_Control!$B$2)} | V2: {=INDEX(Report_Export!V:V,Report_Control!$B$2)} | W2: {=INDEX(Report_Export!W:W,Report_Control!$B$2)} | X2: {=INDEX(Report_Export!X:X,Report_Control!$B$2)} | Y2: {=INDEX(Report_Export!Y:Y,Report_Control!$B$2)} | Z2: {=INDEX(Report_Export!Z:Z,Report_Control!$B$2)} | AA2: {=INDEX(Report_Export!AA:AA,Report_Control!$B$2)} | AB2: {=INDEX(Report_Export!AB:AB,Report_Control!$B$2)} | AC2: {=INDEX(Report_Export!AC:AC,Report_Control!$B$2)} | AD2: {=INDEX(Report_Export!AD:AD,Report_Control!$B$2)} | AE2: {=INDEX(Report_Export!AE:AE,Report_Control!$B$2)} | AF2: {=INDEX(Report_Export!AF:AF,Report_Control!$B$2)} | AG2: {=INDEX(Report_Export!AG:AG,Report_Control!$B$2)} | AH2: {=INDEX(Report_Export!AH:AH,Report_Control!$B$2)} | AI2: {=INDEX(Report_Export!AI:AI,Report_Control!$B$2)} | AJ2: {=INDEX(Report_Export!AJ:AJ,Report_Control!$B$2)} | AK2: {=INDEX(Report_Export!AK:AK,Report_Control!$B$2)} | AL2: {=SUBSTITUTE(SUBSTITUTE(INDEX(Report_Export!AL:AL,Report_Control!$B$2),CHAR(13),""),CHAR(10),"<br><br>")} | AM2: {=SUBSTITUTE(SUBSTITUTE(INDEX(Report_Export!AM:AM,Report_Control!$B$2),CHAR(13),""),CHAR(10),"<br><br>")} | AN2: {=SUBSTITUTE(SUBSTITUTE(INDEX(Report_Export!AN:AN,Report_Control!$B$2),CHAR(13),""),CHAR(10),"<br><br>")}

Sheet Version_Notes
A1: Date | B1: Version | C1: Notes
A2: 2026-06-16 | B2: 0.1 | C2: Starter workbook generated from local Fruit of the Spirit assessment project.

Sheet Reviewer_Roster_360
A1: Participant_ID | B1: Reviewer_ID | C1: Reviewer_Name | D1: Reviewer_Email | E1: Reviewer_Relationship | F1: Reviewer_Group | G1: Invite_Status | H1: Invite_Sent_At | I1: Submitted_At | J1: Response_ID | K1: Invite_Link | L1: Notes
A2: FL360-SAMPLE | B2: SELF-SAMPLE | C2: Sample Person | D2: sample@example.com | E2: Self | F2: Self | G2: Submitted | H2: 2026-07-17T18:10:00Z | I2: 2026-07-17T18:10:00Z | J2: RESP-SAMPLE-SELF | L2: Sample self response
A3: FL360-SAMPLE | B3: OBS-SAMPLE-1 | C3: Observer One | D3: observer1@example.com | E3: Close friend | F3: Close Relationship | G3: Submitted | H3: 2026-07-17T18:10:00Z | I3: 2026-07-17T18:11:00Z | J3: RESP-SAMPLE-OBS1 | L3: Sample observer response
A4: FL360-SAMPLE | B4: OBS-SAMPLE-2 | C4: Observer Two | D4: observer2@example.com | E4: Ministry teammate | F4: Ministry / Team | G4: Submitted | H4: 2026-07-17T18:10:00Z | I4: 2026-07-17T18:12:00Z | J4: RESP-SAMPLE-OBS2 | L4: Sample observer response
A5: FL360-SAMPLE | B5: OBS-SAMPLE-3 | C5: Observer Three | D5: observer3@example.com | E5: Mentor / leader | F5: Mentor / Leader | G5: Submitted | H5: 2026-07-17T18:10:00Z | I5: 2026-07-17T18:13:00Z | J5: RESP-SAMPLE-OBS3 | L5: Sample observer response

Sheet Score_Aggregates_360
A1: Participant_ID | B1: Question_ID | C1: Fruit | D1: Self_Score | E1: Observer_Avg | F1: Close_Relationship_Avg | G1: Ministry_Team_Avg | H1: Mentor_Leader_Avg | I1: All_Observer_Avg | J1: Awareness_Gap | K1: Gap_Category | L1: Report_Note
A2: FL360-SAMPLE | B2: LOVE_01 | C2: Love | D2: =IFERROR(AVERAGEIFS(Response_Intake!$H:$H,Response_Intake!$B:$B,$A2,Response_Intake!$BA:$BA,"Self"),"") -> 4 | E2: =IFERROR(AVERAGEIFS(Response_Intake!$H:$H,Response_Intake!$B:$B,$A2,Response_Intake!$BA:$BA,"<>Self",Response_Intake!$BA:$BA,"<>"),"") -> 4.3333333 | F2: =IFERROR(AVERAGEIFS(Response_Intake!$H:$H,Response_Intake!$B:$B,$A2,Response_Intake!$BA:$BA,"Close Relationship"),"") -> 5 | G2: =IFERROR(AVERAGEIFS(Response_Intake!$H:$H,Response_Intake!$B:$B,$A2,Response_Intake!$BA:$BA,"Ministry / Team"),"") -> 4 | H2: =IFERROR(AVERAGEIFS(Response_Intake!$H:$H,Response_Intake!$B:$B,$A2,Response_Intake!$BA:$BA,"Mentor / Leader"),"") -> 4 | I2: =IFERROR(AVERAGE(F2:H2),"") -> 4.3333333 | J2: =IF(OR(D2="",I2=""),"",I2-D2) -> 0.33333333 | K2: =IF(J2="","",IF(J2>=1,"Encouragement Others See",IF(J2<=-1,"Growth Invitation","Aligned"))) -> Aligned | L2: =IF(K2="Encouragement Others See","Observers see this more strongly than the participant may realize.",IF(K2="Growth Invitation","The participant may experience this as more visible than observers currently see.","Self and observers are generally aligned.")) -> Self and observers are generally aligned.
A3: FL360-SAMPLE | B3: LOVE_02 | C3: Love | D3: =IFERROR(AVERAGEIFS(Response_Intake!$I:$I,Response_Intake!$B:$B,$A3,Response_Intake!$BA:$BA,"Self"),"") -> 5 | E3: =IFERROR(AVERAGEIFS(Response_Intake!$I:$I,Response_Intake!$B:$B,$A3,Response_Intake!$BA:$BA,"<>Self",Response_Intake!$BA:$BA,"<>"),"") -> 4.6666667 | F3: =IFERROR(AVERAGEIFS(Response_Intake!$I:$I,Response_Intake!$B:$B,$A3,Response_Intake!$BA:$BA,"Close Relationship"),"") -> 5 | G3: =IFERROR(AVERAGEIFS(Response_Intake!$I:$I,Response_Intake!$B:$B,$A3,Response_Intake!$BA:$BA,"Ministry / Team"),"") -> 4 | H3: =IFERROR(AVERAGEIFS(Response_Intake!$I:$I,Response_Intake!$B:$B,$A3,Response_Intake!$BA:$BA,"Mentor / Leader"),"") -> 5 | I3: =IFERROR(AVERAGE(F3:H3),"") -> 4.6666667 | J3: =IF(OR(D3="",I3=""),"",I3-D3) -> -0.33333333 | K3: =IF(J3="","",IF(J3>=1,"Encouragement Others See",IF(J3<=-1,"Growth Invitation","Aligned"))) -> Aligned | L3: =IF(K3="Encouragement Others See","Observers see this more strongly than the participant may realize.",IF(K3="Growth Invitation","The participant may experience this as more visible than observers currently see.","Self and observers are generally aligned.")) -> Self and observers are generally aligned.
A4: FL360-SAMPLE | B4: LOVE_03 | C4: Love | D4: =IFERROR(AVERAGEIFS(Response_Intake!$J:$J,Response_Intake!$B:$B,$A4,Response_Intake!$BA:$BA,"Self"),"") -> 4 | E4: =IFERROR(AVERAGEIFS(Response_Intake!$J:$J,Response_Intake!$B:$B,$A4,Response_Intake!$BA:$BA,"<>Self",Response_Intake!$BA:$BA,"<>"),"") -> 4.6666667 | F4: =IFERROR(AVERAGEIFS(Response_Intake!$J:$J,Response_Intake!$B:$B,$A4,Response_Intake!$BA:$BA,"Close Relationship"),"") -> 4 | G4: =IFERROR(AVERAGEIFS(Response_Intake!$J:$J,Response_Intake!$B:$B,$A4,Response_Intake!$BA:$BA,"Ministry / Team"),"") -> 5 | H4: =IFERROR(AVERAGEIFS(Response_Intake!$J:$J,Response_Intake!$B:$B,$A4,Response_Intake!$BA:$BA,"Mentor / Leader"),"") -> 5 | I4: =IFERROR(AVERAGE(F4:H4),"") -> 4.6666667 | J4: =IF(OR(D4="",I4=""),"",I4-D4) -> 0.66666667 | K4: =IF(J4="","",IF(J4>=1,"Encouragement Others See",IF(J4<=-1,"Growth Invitation","Aligned"))) -> Aligned | L4: =IF(K4="Encouragement Others See","Observers see this more strongly than the participant may realize.",IF(K4="Growth Invitation","The participant may experience this as more visible than observers currently see.","Self and observers are generally aligned.")) -> Self and observers are generally aligned.
A5: FL360-SAMPLE | B5: JOY_01 | C5: Joy | D5: =IFERROR(AVERAGEIFS(Response_Intake!$K:$K,Response_Intake!$B:$B,$A5,Response_Intake!$BA:$BA,"Self"),"") -> 3 | E5: =IFERROR(AVERAGEIFS(Response_Intake!$K:$K,Response_Intake!$B:$B,$A5,Response_Intake!$BA:$BA,"<>Self",Response_Intake!$BA:$BA,"<>"),"") -> 3.6666667 | F5: =IFERROR(AVERAGEIFS(Response_Intake!$K:$K,Response_Intake!$B:$B,$A5,Response_Intake!$BA:$BA,"Close Relationship"),"") -> 4 | G5: =IFERROR(AVERAGEIFS(Response_Intake!$K:$K,Response_Intake!$B:$B,$A5,Response_Intake!$BA:$BA,"Ministry / Team"),"") -> 3 | H5: =IFERROR(AVERAGEIFS(Response_Intake!$K:$K,Response_Intake!$B:$B,$A5,Response_Intake!$BA:$BA,"Mentor / Leader"),"") -> 4 | I5: =IFERROR(AVERAGE(F5:H5),"") -> 3.6666667 | J5: =IF(OR(D5="",I5=""),"",I5-D5) -> 0.66666667 | K5: =IF(J5="","",IF(J5>=1,"Encouragement Others See",IF(J5<=-1,"Growth Invitation","Aligned"))) -> Aligned | L5: =IF(K5="Encouragement Others See","Observers see this more strongly than the participant may realize.",IF(K5="Growth Invitation","The participant may experience this as more visible than observers currently see.","Self and observers are generally aligned.")) -> Self and observers are generally aligned.
A6: FL360-SAMPLE | B6: JOY_02 | C6: Joy | D6: =IFERROR(AVERAGEIFS(Response_Intake!$L:$L,Response_Intake!$B:$B,$A6,Response_Intake!$BA:$BA,"Self"),"") -> 4 | E6: =IFERROR(AVERAGEIFS(Response_Intake!$L:$L,Response_Intake!$B:$B,$A6,Response_Intake!$BA:$BA,"<>Self",Response_Intake!$BA:$BA,"<>"),"") -> 4 | F6: =IFERROR(AVERAGEIFS(Response_Intake!$L:$L,Response_Intake!$B:$B,$A6,Response_Intake!$BA:$BA,"Close Relationship"),"") -> 4 | G6: =IFERROR(AVERAGEIFS(Response_Intake!$L:$L,Response_Intake!$B:$B,$A6,Response_Intake!$BA:$BA,"Ministry / Team"),"") -> 4 | H6: =IFERROR(AVERAGEIFS(Response_Intake!$L:$L,Response_Intake!$B:$B,$A6,Response_Intake!$BA:$BA,"Mentor / Leader"),"") -> 4 | I6: =IFERROR(AVERAGE(F6:H6),"") -> 4 | J6: =IF(OR(D6="",I6=""),"",I6-D6) -> 0 | K6: =IF(J6="","",IF(J6>=1,"Encouragement Others See",IF(J6<=-1,"Growth Invitation","Aligned"))) -> Aligned | L6: =IF(K6="Encouragement Others See","Observers see this more strongly than the participant may realize.",IF(K6="Growth Invitation","The participant may experience this as more visible than observers currently see.","Self and observers are generally aligned.")) -> Self and observers are generally aligned.
A7: FL360-SAMPLE | B7: JOY_03 | C7: Joy | D7: =IFERROR(AVERAGEIFS(Response_Intake!$M:$M,Response_Intake!$B:$B,$A7,Response_Intake!$BA:$BA,"Self"),"") -> 4 | E7: =IFERROR(AVERAGEIFS(Response_Intake!$M:$M,Response_Intake!$B:$B,$A7,Response_Intake!$BA:$BA,"<>Self",Response_Intake!$BA:$BA,"<>"),"") -> 3.6666667 | F7: =IFERROR(AVERAGEIFS(Response_Intake!$M:$M,Response_Intake!$B:$B,$A7,Response_Intake!$BA:$BA,"Close Relationship"),"") -> 4 | G7: =IFERROR(AVERAGEIFS(Response_Intake!$M:$M,Response_Intake!$B:$B,$A7,Response_Intake!$BA:$BA,"Ministry / Team"),"") -> 3 | H7: =IFERROR(AVERAGEIFS(Response_Intake!$M:$M,Response_Intake!$B:$B,$A7,Response_Intake!$BA:$BA,"Mentor / Leader"),"") -> 4 | I7: =IFERROR(AVERAGE(F7:H7),"") -> 3.6666667 | J7: =IF(OR(D7="",I7=""),"",I7-D7) -> -0.33333333 | K7: =IF(J7="","",IF(J7>=1,"Encouragement Others See",IF(J7<=-1,"Growth Invitation","Aligned"))) -> Aligned | L7: =IF(K7="Encouragement Others See","Observers see this more strongly than the participant may realize.",IF(K7="Growth Invitation","The participant may experience this as more visible than observers currently see.","Self and observers are generally aligned.")) -> Self and observers are generally aligned.
A8: FL360-SAMPLE | B8: PEACE_01 | C8: Peace | D8: =IFERROR(AVERAGEIFS(Response_Intake!$N:$N,Response_Intake!$B:$B,$A8,Response_Intake!$BA:$BA,"Self"),"") -> 4 | E8: =IFERROR(AVERAGEIFS(Response_Intake!$N:$N,Response_Intake!$B:$B,$A8,Response_Intake!$BA:$BA,"<>Self",Response_Intake!$BA:$BA,"<>"),"") -> 4.3333333 | F8: =IFERROR(AVERAGEIFS(Response_Intake!$N:$N,Response_Intake!$B:$B,$A8,Response_Intake!$BA:$BA,"Close Relationship"),"") -> 5 | G8: =IFERROR(AVERAGEIFS(Response_Intake!$N:$N,Response_Intake!$B:$B,$A8,Response_Intake!$BA:$BA,"Ministry / Team"),"") -> 4 | H8: =IFERROR(AVERAGEIFS(Response_Intake!$N:$N,Response_Intake!$B:$B,$A8,Response_Intake!$BA:$BA,"Mentor / Leader"),"") -> 4 | I8: =IFERROR(AVERAGE(F8:H8),"") -> 4.3333333 | J8: =IF(OR(D8="",I8=""),"",I8-D8) -> 0.33333333 | K8: =IF(J8="","",IF(J8>=1,"Encouragement Others See",IF(J8<=-1,"Growth Invitation","Aligned"))) -> Aligned | L8: =IF(K8="Encouragement Others See","Observers see this more strongly than the participant may realize.",IF(K8="Growth Invitation","The participant may experience this as more visible than observers currently see.","Self and observers are generally aligned.")) -> Self and observers are generally aligned.
A9: FL360-SAMPLE | B9: PEACE_02 | C9: Peace | D9: =IFERROR(AVERAGEIFS(Response_Intake!$O:$O,Response_Intake!$B:$B,$A9,Response_Intake!$BA:$BA,"Self"),"") -> 4 | E9: =IFERROR(AVERAGEIFS(Response_Intake!$O:$O,Response_Intake!$B:$B,$A9,Response_Intake!$BA:$BA,"<>Self",Response_Intake!$BA:$BA,"<>"),"") -> 4.3333333 | F9: =IFERROR(AVERAGEIFS(Response_Intake!$O:$O,Response_Intake!$B:$B,$A9,Response_Intake!$BA:$BA,"Close Relationship"),"") -> 4 | G9: =IFERROR(AVERAGEIFS(Response_Intake!$O:$O,Response_Intake!$B:$B,$A9,Response_Intake!$BA:$BA,"Ministry / Team"),"") -> 4 | H9: =IFERROR(AVERAGEIFS(Response_Intake!$O:$O,Response_Intake!$B:$B,$A9,Response_Intake!$BA:$BA,"Mentor / Leader"),"") -> 5 | I9: =IFERROR(AVERAGE(F9:H9),"") -> 4.3333333 | J9: =IF(OR(D9="",I9=""),"",I9-D9) -> 0.33333333 | K9: =IF(J9="","",IF(J9>=1,"Encouragement Others See",IF(J9<=-1,"Growth Invitation","Aligned"))) -> Aligned | L9: =IF(K9="Encouragement Others See","Observers see this more strongly than the participant may realize.",IF(K9="Growth Invitation","The participant may experience this as more visible than observers currently see.","Self and observers are generally aligned.")) -> Self and observers are generally aligned.
A10: FL360-SAMPLE | B10: PEACE_03 | C10: Peace | D10: =IFERROR(AVERAGEIFS(Response_Intake!$P:$P,Response_Intake!$B:$B,$A10,Response_Intake!$BA:$BA,"Self"),"") -> 5 | E10: =IFERROR(AVERAGEIFS(Response_Intake!$P:$P,Response_Intake!$B:$B,$A10,Response_Intake!$BA:$BA,"<>Self",Response_Intake!$BA:$BA,"<>"),"") -> 4.6666667 | F10: =IFERROR(AVERAGEIFS(Response_Intake!$P:$P,Response_Intake!$B:$B,$A10,Response_Intake!$BA:$BA,"Close Relationship"),"") -> 5 | G10: =IFERROR(AVERAGEIFS(Response_Intake!$P:$P,Response_Intake!$B:$B,$A10,Response_Intake!$BA:$BA,"Ministry / Team"),"") -> 4 | H10: =IFERROR(AVERAGEIFS(Response_Intake!$P:$P,Response_Intake!$B:$B,$A10,Response_Intake!$BA:$BA,"Mentor / Leader"),"") -> 5 | I10: =IFERROR(AVERAGE(F10:H10),"") -> 4.6666667 | J10: =IF(OR(D10="",I10=""),"",I10-D10) -> -0.33333333 | K10: =IF(J10="","",IF(J10>=1,"Encouragement Others See",IF(J10<=-1,"Growth Invitation","Aligned"))) -> Aligned | L10: =IF(K10="Encouragement Others See","Observers see this more strongly than the participant may realize.",IF(K10="Growth Invitation","The participant may experience this as more visible than observers currently see.","Self and observers are generally aligned.")) -> Self and observers are generally aligned.
A11: FL360-SAMPLE | B11: PATIENCE_01 | C11: Patience | D11: =IFERROR(AVERAGEIFS(Response_Intake!$Q:$Q,Response_Intake!$B:$B,$A11,Response_Intake!$BA:$BA,"Self"),"") -> 3 | E11: =IFERROR(AVERAGEIFS(Response_Intake!$Q:$Q,Response_Intake!$B:$B,$A11,Response_Intake!$BA:$BA,"<>Self",Response_Intake!$BA:$BA,"<>"),"") -> 3.3333333 | F11: =IFERROR(AVERAGEIFS(Response_Intake!$Q:$Q,Response_Intake!$B:$B,$A11,Response_Intake!$BA:$BA,"Close Relationship"),"") -> 3 | G11: =IFERROR(AVERAGEIFS(Response_Intake!$Q:$Q,Response_Intake!$B:$B,$A11,Response_Intake!$BA:$BA,"Ministry / Team"),"") -> 3 | H11: =IFERROR(AVERAGEIFS(Response_Intake!$Q:$Q,Response_Intake!$B:$B,$A11,Response_Intake!$BA:$BA,"Mentor / Leader"),"") -> 4 | I11: =IFERROR(AVERAGE(F11:H11),"") -> 3.3333333 | J11: =IF(OR(D11="",I11=""),"",I11-D11) -> 0.33333333 | K11: =IF(J11="","",IF(J11>=1,"Encouragement Others See",IF(J11<=-1,"Growth Invitation","Aligned"))) -> Aligned | L11: =IF(K11="Encouragement Others See","Observers see this more strongly than the participant may realize.",IF(K11="Growth Invitation","The participant may experience this as more visible than observers currently see.","Self and observers are generally aligned.")) -> Self and observers are generally aligned.
A12: FL360-SAMPLE | B12: PATIENCE_02 | C12: Patience | D12: =IFERROR(AVERAGEIFS(Response_Intake!$R:$R,Response_Intake!$B:$B,$A12,Response_Intake!$BA:$BA,"Self"),"") -> 3 | E12: =IFERROR(AVERAGEIFS(Response_Intake!$R:$R,Response_Intake!$B:$B,$A12,Response_Intake!$BA:$BA,"<>Self",Response_Intake!$BA:$BA,"<>"),"") -> 3.3333333 | F12: =IFERROR(AVERAGEIFS(Response_Intake!$R:$R,Response_Intake!$B:$B,$A12,Response_Intake!$BA:$BA,"Close Relationship"),"") -> 4 | G12: =IFERROR(AVERAGEIFS(Response_Intake!$R:$R,Response_Intake!$B:$B,$A12,Response_Intake!$BA:$BA,"Ministry / Team"),"") -> 3 | H12: =IFERROR(AVERAGEIFS(Response_Intake!$R:$R,Response_Intake!$B:$B,$A12,Response_Intake!$BA:$BA,"Mentor / Leader"),"") -> 3 | I12: =IFERROR(AVERAGE(F12:H12),"") -> 3.3333333 | J12: =IF(OR(D12="",I12=""),"",I12-D12) -> 0.33333333 | K12: =IF(J12="","",IF(J12>=1,"Encouragement Others See",IF(J12<=-1,"Growth Invitation","Aligned"))) -> Aligned | L12: =IF(K12="Encouragement Others See","Observers see this more strongly than the participant may realize.",IF(K12="Growth Invitation","The participant may experience this as more visible than observers currently see.","Self and observers are generally aligned.")) -> Self and observers are generally aligned.
A13: FL360-SAMPLE | B13: PATIENCE_03 | C13: Patience | D13: =IFERROR(AVERAGEIFS(Response_Intake!$S:$S,Response_Intake!$B:$B,$A13,Response_Intake!$BA:$BA,"Self"),"") -> 4 | E13: =IFERROR(AVERAGEIFS(Response_Intake!$S:$S,Response_Intake!$B:$B,$A13,Response_Intake!$BA:$BA,"<>Self",Response_Intake!$BA:$BA,"<>"),"") -> 3.3333333 | F13: =IFERROR(AVERAGEIFS(Response_Intake!$S:$S,Response_Intake!$B:$B,$A13,Response_Intake!$BA:$BA,"Close Relationship"),"") -> 3 | G13: =IFERROR(AVERAGEIFS(Response_Intake!$S:$S,Response_Intake!$B:$B,$A13,Response_Intake!$BA:$BA,"Ministry / Team"),"") -> 3 | H13: =IFERROR(AVERAGEIFS(Response_Intake!$S:$S,Response_Intake!$B:$B,$A13,Response_Intake!$BA:$BA,"Mentor / Leader"),"") -> 4 | I13: =IFERROR(AVERAGE(F13:H13),"") -> 3.3333333 | J13: =IF(OR(D13="",I13=""),"",I13-D13) -> -0.66666667 | K13: =IF(J13="","",IF(J13>=1,"Encouragement Others See",IF(J13<=-1,"Growth Invitation","Aligned"))) -> Aligned | L13: =IF(K13="Encouragement Others See","Observers see this more strongly than the participant may realize.",IF(K13="Growth Invitation","The participant may experience this as more visible than observers currently see.","Self and observers are generally aligned.")) -> Self and observers are generally aligned.
A14: FL360-SAMPLE | B14: KINDNESS_01 | C14: Kindness | D14: =IFERROR(AVERAGEIFS(Response_Intake!$T:$T,Response_Intake!$B:$B,$A14,Response_Intake!$BA:$BA,"Self"),"") -> 5 | E14: =IFERROR(AVERAGEIFS(Response_Intake!$T:$T,Response_Intake!$B:$B,$A14,Response_Intake!$BA:$BA,"<>Self",Response_Intake!$BA:$BA,"<>"),"") -> 4.6666667 | F14: =IFERROR(AVERAGEIFS(Response_Intake!$T:$T,Response_Intake!$B:$B,$A14,Response_Intake!$BA:$BA,"Close Relationship"),"") -> 5 | G14: =IFERROR(AVERAGEIFS(Response_Intake!$T:$T,Response_Intake!$B:$B,$A14,Response_Intake!$BA:$BA,"Ministry / Team"),"") -> 4 | H14: =IFERROR(AVERAGEIFS(Response_Intake!$T:$T,Response_Intake!$B:$B,$A14,Response_Intake!$BA:$BA,"Mentor / Leader"),"") -> 5 | I14: =IFERROR(AVERAGE(F14:H14),"") -> 4.6666667 | J14: =IF(OR(D14="",I14=""),"",I14-D14) -> -0.33333333 | K14: =IF(J14="","",IF(J14>=1,"Encouragement Others See",IF(J14<=-1,"Growth Invitation","Aligned"))) -> Aligned | L14: =IF(K14="Encouragement Others See","Observers see this more strongly than the participant may realize.",IF(K14="Growth Invitation","The participant may experience this as more visible than observers currently see.","Self and observers are generally aligned.")) -> Self and observers are generally aligned.
A15: FL360-SAMPLE | B15: KINDNESS_02 | C15: Kindness | D15: =IFERROR(AVERAGEIFS(Response_Intake!$U:$U,Response_Intake!$B:$B,$A15,Response_Intake!$BA:$BA,"Self"),"") -> 4 | E15: =IFERROR(AVERAGEIFS(Response_Intake!$U:$U,Response_Intake!$B:$B,$A15,Response_Intake!$BA:$BA,"<>Self",Response_Intake!$BA:$BA,"<>"),"") -> 4.6666667 | F15: =IFERROR(AVERAGEIFS(Response_Intake!$U:$U,Response_Intake!$B:$B,$A15,Response_Intake!$BA:$BA,"Close Relationship"),"") -> 5 | G15: =IFERROR(AVERAGEIFS(Response_Intake!$U:$U,Response_Intake!$B:$B,$A15,Response_Intake!$BA:$BA,"Ministry / Team"),"") -> 5 | H15: =IFERROR(AVERAGEIFS(Response_Intake!$U:$U,Response_Intake!$B:$B,$A15,Response_Intake!$BA:$BA,"Mentor / Leader"),"") -> 4 | I15: =IFERROR(AVERAGE(F15:H15),"") -> 4.6666667 | J15: =IF(OR(D15="",I15=""),"",I15-D15) -> 0.66666667 | K15: =IF(J15="","",IF(J15>=1,"Encouragement Others See",IF(J15<=-1,"Growth Invitation","Aligned"))) -> Aligned | L15: =IF(K15="Encouragement Others See","Observers see this more strongly than the participant may realize.",IF(K15="Growth Invitation","The participant may experience this as more visible than observers currently see.","Self and observers are generally aligned.")) -> Self and observers are generally aligned.
A16: FL360-SAMPLE | B16: KINDNESS_03 | C16: Kindness | D16: =IFERROR(AVERAGEIFS(Response_Intake!$V:$V,Response_Intake!$B:$B,$A16,Response_Intake!$BA:$BA,"Self"),"") -> 5 | E16: =IFERROR(AVERAGEIFS(Response_Intake!$V:$V,Response_Intake!$B:$B,$A16,Response_Intake!$BA:$BA,"<>Self",Response_Intake!$BA:$BA,"<>"),"") -> 4.6666667 | F16: =IFERROR(AVERAGEIFS(Response_Intake!$V:$V,Response_Intake!$B:$B,$A16,Response_Intake!$BA:$BA,"Close Relationship"),"") -> 5 | G16: =IFERROR(AVERAGEIFS(Response_Intake!$V:$V,Response_Intake!$B:$B,$A16,Response_Intake!$BA:$BA,"Ministry / Team"),"") -> 4 | H16: =IFERROR(AVERAGEIFS(Response_Intake!$V:$V,Response_Intake!$B:$B,$A16,Response_Intake!$BA:$BA,"Mentor / Leader"),"") -> 5 | I16: =IFERROR(AVERAGE(F16:H16),"") -> 4.6666667 | J16: =IF(OR(D16="",I16=""),"",I16-D16) -> -0.33333333 | K16: =IF(J16="","",IF(J16>=1,"Encouragement Others See",IF(J16<=-1,"Growth Invitation","Aligned"))) -> Aligned | L16: =IF(K16="Encouragement Others See","Observers see this more strongly than the participant may realize.",IF(K16="Growth Invitation","The participant may experience this as more visible than observers currently see.","Self and observers are generally aligned.")) -> Self and observers are generally aligned.
A17: FL360-SAMPLE | B17: GOODNESS_01 | C17: Goodness | D17: =IFERROR(AVERAGEIFS(Response_Intake!$W:$W,Response_Intake!$B:$B,$A17,Response_Intake!$BA:$BA,"Self"),"") -> 4 | E17: =IFERROR(AVERAGEIFS(Response_Intake!$W:$W,Response_Intake!$B:$B,$A17,Response_Intake!$BA:$BA,"<>Self",Response_Intake!$BA:$BA,"<>"),"") -> 4 | F17: =IFERROR(AVERAGEIFS(Response_Intake!$W:$W,Response_Intake!$B:$B,$A17,Response_Intake!$BA:$BA,"Close Relationship"),"") -> 4 | G17: =IFERROR(AVERAGEIFS(Response_Intake!$W:$W,Response_Intake!$B:$B,$A17,Response_Intake!$BA:$BA,"Ministry / Team"),"") -> 4 | H17: =IFERROR(AVERAGEIFS(Response_Intake!$W:$W,Response_Intake!$B:$B,$A17,Response_Intake!$BA:$BA,"Mentor / Leader"),"") -> 4 | I17: =IFERROR(AVERAGE(F17:H17),"") -> 4 | J17: =IF(OR(D17="",I17=""),"",I17-D17) -> 0 | K17: =IF(J17="","",IF(J17>=1,"Encouragement Others See",IF(J17<=-1,"Growth Invitation","Aligned"))) -> Aligned | L17: =IF(K17="Encouragement Others See","Observers see this more strongly than the participant may realize.",IF(K17="Growth Invitation","The participant may experience this as more visible than observers currently see.","Self and observers are generally aligned.")) -> Self and observers are generally aligned.
A18: FL360-SAMPLE | B18: GOODNESS_02 | C18: Goodness | D18: =IFERROR(AVERAGEIFS(Response_Intake!$X:$X,Response_Intake!$B:$B,$A18,Response_Intake!$BA:$BA,"Self"),"") -> 4 | E18: =IFERROR(AVERAGEIFS(Response_Intake!$X:$X,Response_Intake!$B:$B,$A18,Response_Intake!$BA:$BA,"<>Self",Response_Intake!$BA:$BA,"<>"),"") -> 4.3333333 | F18: =IFERROR(AVERAGEIFS(Response_Intake!$X:$X,Response_Intake!$B:$B,$A18,Response_Intake!$BA:$BA,"Close Relationship"),"") -> 4 | G18: =IFERROR(AVERAGEIFS(Response_Intake!$X:$X,Response_Intake!$B:$B,$A18,Response_Intake!$BA:$BA,"Ministry / Team"),"") -> 4 | H18: =IFERROR(AVERAGEIFS(Response_Intake!$X:$X,Response_Intake!$B:$B,$A18,Response_Intake!$BA:$BA,"Mentor / Leader"),"") -> 5 | I18: =IFERROR(AVERAGE(F18:H18),"") -> 4.3333333 | J18: =IF(OR(D18="",I18=""),"",I18-D18) -> 0.33333333 | K18: =IF(J18="","",IF(J18>=1,"Encouragement Others See",IF(J18<=-1,"Growth Invitation","Aligned"))) -> Aligned | L18: =IF(K18="Encouragement Others See","Observers see this more strongly than the participant may realize.",IF(K18="Growth Invitation","The participant may experience this as more visible than observers currently see.","Self and observers are generally aligned.")) -> Self and observers are generally aligned.
A19: FL360-SAMPLE | B19: GOODNESS_03 | C19: Goodness | D19: =IFERROR(AVERAGEIFS(Response_Intake!$Y:$Y,Response_Intake!$B:$B,$A19,Response_Intake!$BA:$BA,"Self"),"") -> 4 | E19: =IFERROR(AVERAGEIFS(Response_Intake!$Y:$Y,Response_Intake!$B:$B,$A19,Response_Intake!$BA:$BA,"<>Self",Response_Intake!$BA:$BA,"<>"),"") -> 4.3333333 | F19: =IFERROR(AVERAGEIFS(Response_Intake!$Y:$Y,Response_Intake!$B:$B,$A19,Response_Intake!$BA:$BA,"Close Relationship"),"") -> 4 | G19: =IFERROR(AVERAGEIFS(Response_Intake!$Y:$Y,Response_Intake!$B:$B,$A19,Response_Intake!$BA:$BA,"Ministry / Team"),"") -> 5 | H19: =IFERROR(AVERAGEIFS(Response_Intake!$Y:$Y,Response_Intake!$B:$B,$A19,Response_Intake!$BA:$BA,"Mentor / Leader"),"") -> 4 | I19: =IFERROR(AVERAGE(F19:H19),"") -> 4.3333333 | J19: =IF(OR(D19="",I19=""),"",I19-D19) -> 0.33333333 | K19: =IF(J19="","",IF(J19>=1,"Encouragement Others See",IF(J19<=-1,"Growth Invitation","Aligned"))) -> Aligned | L19: =IF(K19="Encouragement Others See","Observers see this more strongly than the participant may realize.",IF(K19="Growth Invitation","The participant may experience this as more visible than observers currently see.","Self and observers are generally aligned.")) -> Self and observers are generally aligned.
A20: FL360-SAMPLE | B20: FAITHFULNESS_01 | C20: Faithfulness | D20: =IFERROR(AVERAGEIFS(Response_Intake!$Z:$Z,Response_Intake!$B:$B,$A20,Response_Intake!$BA:$BA,"Self"),"") -> 5 | E20: =IFERROR(AVERAGEIFS(Response_Intake!$Z:$Z,Response_Intake!$B:$B,$A20,Response_Intake!$BA:$BA,"<>Self",Response_Intake!$BA:$BA,"<>"),"") -> 5 | F20: =IFERROR(AVERAGEIFS(Response_Intake!$Z:$Z,Response_Intake!$B:$B,$A20,Response_Intake!$BA:$BA,"Close Relationship"),"") -> 5 | G20: =IFERROR(AVERAGEIFS(Response_Intake!$Z:$Z,Response_Intake!$B:$B,$A20,Response_Intake!$BA:$BA,"Ministry / Team"),"") -> 5 | H20: =IFERROR(AVERAGEIFS(Response_Intake!$Z:$Z,Response_Intake!$B:$B,$A20,Response_Intake!$BA:$BA,"Mentor / Leader"),"") -> 5 | I20: =IFERROR(AVERAGE(F20:H20),"") -> 5 | J20: =IF(OR(D20="",I20=""),"",I20-D20) -> 0 | K20: =IF(J20="","",IF(J20>=1,"Encouragement Others See",IF(J20<=-1,"Growth Invitation","Aligned"))) -> Aligned | L20: =IF(K20="Encouragement Others See","Observers see this more strongly than the participant may realize.",IF(K20="Growth Invitation","The participant may experience this as more visible than observers currently see.","Self and observers are generally aligned.")) -> Self and observers are generally aligned.
A21: FL360-SAMPLE | B21: FAITHFULNESS_02 | C21: Faithfulness | D21: =IFERROR(AVERAGEIFS(Response_Intake!$AA:$AA,Response_Intake!$B:$B,$A21,Response_Intake!$BA:$BA,"Self"),"") -> 4 | E21: =IFERROR(AVERAGEIFS(Response_Intake!$AA:$AA,Response_Intake!$B:$B,$A21,Response_Intake!$BA:$BA,"<>Self",Response_Intake!$BA:$BA,"<>"),"") -> 4.6666667 | F21: =IFERROR(AVERAGEIFS(Response_Intake!$AA:$AA,Response_Intake!$B:$B,$A21,Response_Intake!$BA:$BA,"Close Relationship"),"") -> 4 | G21: =IFERROR(AVERAGEIFS(Response_Intake!$AA:$AA,Response_Intake!$B:$B,$A21,Response_Intake!$BA:$BA,"Ministry / Team"),"") -> 5 | H21: =IFERROR(AVERAGEIFS(Response_Intake!$AA:$AA,Response_Intake!$B:$B,$A21,Response_Intake!$BA:$BA,"Mentor / Leader"),"") -> 5 | I21: =IFERROR(AVERAGE(F21:H21),"") -> 4.6666667 | J21: =IF(OR(D21="",I21=""),"",I21-D21) -> 0.66666667 | K21: =IF(J21="","",IF(J21>=1,"Encouragement Others See",IF(J21<=-1,"Growth Invitation","Aligned"))) -> Aligned | L21: =IF(K21="Encouragement Others See","Observers see this more strongly than the participant may realize.",IF(K21="Growth Invitation","The participant may experience this as more visible than observers currently see.","Self and observers are generally aligned.")) -> Self and observers are generally aligned.
A22: FL360-SAMPLE | B22: FAITHFULNESS_03 | C22: Faithfulness | D22: =IFERROR(AVERAGEIFS(Response_Intake!$AB:$AB,Response_Intake!$B:$B,$A22,Response_Intake!$BA:$BA,"Self"),"") -> 4 | E22: =IFERROR(AVERAGEIFS(Response_Intake!$AB:$AB,Response_Intake!$B:$B,$A22,Response_Intake!$BA:$BA,"<>Self",Response_Intake!$BA:$BA,"<>"),"") -> 4.6666667 | F22: =IFERROR(AVERAGEIFS(Response_Intake!$AB:$AB,Response_Intake!$B:$B,$A22,Response_Intake!$BA:$BA,"Close Relationship"),"") -> 5 | G22: =IFERROR(AVERAGEIFS(Response_Intake!$AB:$AB,Response_Intake!$B:$B,$A22,Response_Intake!$BA:$BA,"Ministry / Team"),"") -> 4 | H22: =IFERROR(AVERAGEIFS(Response_Intake!$AB:$AB,Response_Intake!$B:$B,$A22,Response_Intake!$BA:$BA,"Mentor / Leader"),"") -> 5 | I22: =IFERROR(AVERAGE(F22:H22),"") -> 4.6666667 | J22: =IF(OR(D22="",I22=""),"",I22-D22) -> 0.66666667 | K22: =IF(J22="","",IF(J22>=1,"Encouragement Others See",IF(J22<=-1,"Growth Invitation","Aligned"))) -> Aligned | L22: =IF(K22="Encouragement Others See","Observers see this more strongly than the participant may realize.",IF(K22="Growth Invitation","The participant may experience this as more visible than observers currently see.","Self and observers are generally aligned.")) -> Self and observers are generally aligned.
A23: FL360-SAMPLE | B23: GENTLENESS_01 | C23: Gentleness | D23: =IFERROR(AVERAGEIFS(Response_Intake!$AC:$AC,Response_Intake!$B:$B,$A23,Response_Intake!$BA:$BA,"Self"),"") -> 3 | E23: =IFERROR(AVERAGEIFS(Response_Intake!$AC:$AC,Response_Intake!$B:$B,$A23,Response_Intake!$BA:$BA,"<>Self",Response_Intake!$BA:$BA,"<>"),"") -> 4 | F23: =IFERROR(AVERAGEIFS(Response_Intake!$AC:$AC,Response_Intake!$B:$B,$A23,Response_Intake!$BA:$BA,"Close Relationship"),"") -> 4 | G23: =IFERROR(AVERAGEIFS(Response_Intake!$AC:$AC,Response_Intake!$B:$B,$A23,Response_Intake!$BA:$BA,"Ministry / Team"),"") -> 4 | H23: =IFERROR(AVERAGEIFS(Response_Intake!$AC:$AC,Response_Intake!$B:$B,$A23,Response_Intake!$BA:$BA,"Mentor / Leader"),"") -> 4 | I23: =IFERROR(AVERAGE(F23:H23),"") -> 4 | J23: =IF(OR(D23="",I23=""),"",I23-D23) -> 1 | K23: =IF(J23="","",IF(J23>=1,"Encouragement Others See",IF(J23<=-1,"Growth Invitation","Aligned"))) -> Encouragement Others See | L23: =IF(K23="Encouragement Others See","Observers see this more strongly than the participant may realize.",IF(K23="Growth Invitation","The participant may experience this as more visible than observers currently see.","Self and observers are generally aligned.")) -> Observers see this more strongly than the participant may realize.
